<sdf version='1.5'>
  <model name='arm_and_hand'>
     <link name='shadowarm_handsupport'>
      <pose>-0.08 -1.134 1.0465 -3.14159 2.06823e-13 -3.14159</pose>
      <inertial>
        <pose>0 0 0.072 0 -0 0</pose>
        <mass>3.75</mass>
        <inertia>
          <ixx>0.00596</ixx>
          <ixy>1.73472e-18</ixy>
          <ixz>0</ixz>
          <iyy>0.00596</iyy>
          <iyz>0</iyz>
          <izz>0.0011</izz>
        </inertia>
      </inertial>
      <collision name='shadowarm_handsupport_collision'>
        <pose>0 0 -0.005 0 -0 0</pose>
        <geometry>
          <cylinder>
            <length>0.001</length>
            <radius>0.06</radius>
          </cylinder>
        </geometry>
        <surface>
          <contact>
            <ode/>
          </contact>
          <friction>
            <ode/>
          </friction>
        </surface>
      </collision>
      <collision name='shadowarm_handsupport_collision_forearm'>
        <pose>0 0 0.09 0 -0 2.35619</pose>
        <geometry>
          <cylinder>
            <length>0.18</length>
            <radius>0.06</radius>
          </cylinder>
        </geometry>
        <surface>
          <contact>
            <ode/>
          </contact>
          <friction>
            <ode/>
          </friction>
        </surface>
        <surface>
          <contact>
            <ode/>
          </contact>
          <friction>
            <ode/>
          </friction>
        </surface>
      </collision>
      <visual name='shadowarm_handsupport_visual'>
        <pose>0 0 -0.04 0 -0 0</pose>
        <geometry>
          <mesh>
            <scale>0.001 0.001 0.001</scale>
            <uri>sr_description/arm/model/elbow_rotate_motor.dae</uri>
          </mesh>
        </geometry>
        <material>
          <script>
            <name>Gazebo/Grey</name>
            <uri>__default__</uri>
          </script>
        </material>
      </visual>
      <visual name='shadowarm_handsupport_visual_forearm'>
        <pose>0 0 0 0 -0 2.35619</pose>
        <geometry>
          <!--mesh>
            <scale>0.001 0.001 0.001</scale>
            <uri>sr_description/hand/model/forearm.dae</uri>
          </mesh-->
          <box>
            <size>0.10 0.04 0.14</size>
          </box>
        </geometry>
        <material>
          <script>
            <name>LightGrey</name>
            <uri>__default__</uri>
          </script>
        </material>
      </visual>
      <velocity_decay>
        <linear>0</linear>
        <angular>0</angular>
      </velocity_decay>
      <gravity>1</gravity>
      <velocity_decay>
        <linear>0</linear>
        <angular>0</angular>
      </velocity_decay>
      <self_collide>0</self_collide>
    </link>
    <joint name='ElbowJRotate' type='revolute'>
      <child>shadowarm_handsupport</child>
      <parent>world</parent>
      <axis>
        <xyz>-2.06823e-13 0 1</xyz>
        <limit>
          <lower>-1.5708</lower>
          <upper>1.5708</upper>
          <effort>1000</effort>
          <velocity>10</velocity>
        </limit>
        <dynamics>
          <damping>30</damping>
          <spring_reference>0</spring_reference>
          <spring_stiffness>0</spring_stiffness>
        </dynamics>
        <use_parent_model_frame>1</use_parent_model_frame>
      </axis>
      <physics>
        <provide_feedback>1</provide_feedback>
        <ode>
          <provide_feedback>1</provide_feedback>
          <implicit_spring_damper>1</implicit_spring_damper>
          <cfm_damping>1</cfm_damping>
          <limit>
            <cfm>0</cfm>
            <erp>0.2</erp>
          </limit>
        </ode>
      </physics>
    </joint>
    <link name='wrist'>
      <pose>-0.0870711 -1.12693 0.8335 3.14159 -1.46246e-13 0.785398</pose>
      <inertial>
        <pose>0 0 0 0 -0 0</pose>
        <mass>0.1</mass>
        <inertia>
          <ixx>0.00012</ixx>
          <ixy>0</ixy>
          <ixz>0</ixz>
          <iyy>0.000148</iyy>
          <iyz>0</iyz>
          <izz>4.38e-05</izz>
        </inertia>
      </inertial>
      <collision name='wrist_collision'>
        <pose>0 0 0 0 -0 0</pose>
        <geometry>
          <box>
            <size>0.02 0.02 0.02</size>
          </box>
        </geometry>
        <surface>
          <contact>
            <ode/>
          </contact>
          <friction>
            <ode/>
          </friction>
        </surface>
      </collision>
      <visual name='wrist_visual'>
        <pose>0 0 0 0 -0 0</pose>
        <geometry>
          <mesh>
            <scale>0.001 0.001 0.001</scale>
            <uri>sr_description/hand/model/wrist.dae</uri>
          </mesh>
        </geometry>
        <material>
          <script>
            <name>PR2/Grey2</name>
            <uri>__default__</uri>
          </script>
        </material>
      </visual>
      <gravity>1</gravity>
      <velocity_decay>
        <linear>0</linear>
        <angular>0</angular>
      </velocity_decay>
      <self_collide>0</self_collide>
    </link>
    <joint name='WRJ2' type='revolute'>
      <child>wrist</child>
      <parent>shadowarm_handsupport</parent>
      <axis>
        <xyz>0.707107 -0.707107 1.46246e-13</xyz>
        <limit>
          <lower>-0.523599</lower>
          <upper>0.174533</upper>
          <effort>1000</effort>
          <velocity>10</velocity>
        </limit>
        <dynamics>
          <damping>30</damping>
          <spring_reference>0</spring_reference>
          <spring_stiffness>0</spring_stiffness>
        </dynamics>
        <use_parent_model_frame>1</use_parent_model_frame>
      </axis>
      <physics>
        <provide_feedback>1</provide_feedback>
        <ode>
          <provide_feedback>1</provide_feedback>
          <implicit_spring_damper>1</implicit_spring_damper>
          <cfm_damping>1</cfm_damping>
          <limit>
            <cfm>0</cfm>
            <erp>0.2</erp>
          </limit>
        </ode>
      </physics>
    </joint>
    <link name='palm'>
      <pose>-0.0870711 -1.12693 0.7995 3.14159 -1.46246e-13 0.785398</pose>
      <inertial>
        <pose>0 0 0.035 0 -0 0</pose>
        <mass>0.3</mass>
        <inertia>
          <ixx>0.0005</ixx>
          <ixy>0</ixy>
          <ixz>0</ixz>
          <iyy>0.0005</iyy>
          <iyz>0</iyz>
          <izz>0.0003</izz>
        </inertia>
      </inertial>
      <collision name='palm_collision'>
        <pose>0.005 0 0.035 0 -0 0</pose>
        <geometry>
          <box>
            <size>0.05 0.02 0.07</size>
          </box>
        </geometry>
        <surface>
          <contact>
            <ode/>
          </contact>
          <friction>
            <ode/>
          </friction>
        </surface>
      </collision>
      <visual name='palm_visual'>
        <!--pose>0 0 0 0 -0 0</pose-->
        <pose>0.005 0 0.035 0 -0 0</pose>
        <geometry>
          <box>
            <size>0.05 0.02 0.07</size>
          </box>
          <!--mesh>
            <scale>0.001 0.001 0.001</scale>
            <uri>sr_description/hand/model/palm.dae</uri>
          </mesh-->
        </geometry>
        <material>
          <script>
            <name>LightGrey</name>
            <uri>__default__</uri>
          </script>
        </material>
      </visual>
      <gravity>1</gravity>
      <velocity_decay>
        <linear>0</linear>
        <angular>0</angular>
      </velocity_decay>
      <self_collide>0</self_collide>
      <sensor name='palm_contact' type='contact'>
        <always_on>1</always_on>
        <update_rate>1000</update_rate>
        <contact>
          <collision>palm_collision</collision>
          <topic>palm_collision</topic>
        </contact>
        <plugin name='palm_gazebo_ros_bumper_controller' filename='libgazebo_ros_bumper.so'>
          <updateRate>100.0</updateRate>
          <frameName>palm</frameName>
          <bumperTopicName>contacts/palm</bumperTopicName>
        </plugin>
      </sensor>
    </link>
    <joint name='WRJ1' type='revolute'>
      <child>palm</child>
      <parent>wrist</parent>
      <axis>
        <xyz>0.707107 0.707107 1.46246e-13</xyz>
        <limit>
          <lower>-0.7854</lower>
          <upper>0.5236</upper>
          <effort>1000</effort>
          <velocity>10</velocity>
        </limit>
        <dynamics>
          <damping>30</damping>
          <spring_reference>0</spring_reference>
          <spring_stiffness>0</spring_stiffness>
        </dynamics>
        <use_parent_model_frame>1</use_parent_model_frame>
      </axis>
      <physics>
        <provide_feedback>1</provide_feedback>
        <ode>
          <provide_feedback>1</provide_feedback>
          <implicit_spring_damper>1</implicit_spring_damper>
          <cfm_damping>1</cfm_damping>
          <limit>
            <cfm>0</cfm>
            <erp>0.2</erp>
          </limit>
        </ode>
      </physics>
    </joint>
  </model>
</sdf>
